<?xml version="1.0" ?>
<!-- =================================================================================== -->
<!-- |    This document was autogenerated by xacro from /home/robo/dev_ws/src/open_manipulator/open_manipulator_x_description/urdf/open_manipulator_x_robot.urdf.xacro | -->
<!-- |    EDITING THIS FILE BY HAND IS NOT RECOMMENDED                                 | -->
<!-- =================================================================================== -->
<!-- OpenManipulator Chain -->
<robot name="open_manipulator_x">
  <material name="black">
    <color rgba="0.0 0.0 0.0 1.0"/>
  </material>
  <material name="white">
    <color rgba="1.0 1.0 1.0 1.0"/>
  </material>
  <material name="red">
    <color rgba="0.8 0.0 0.0 1.0"/>
  </material>
  <material name="blue">
    <color rgba="0.0 0.0 0.8 1.0"/>
  </material>
  <material name="green">
    <color rgba="0.0 0.8 0.0 1.0"/>
  </material>
  <material name="grey">
    <color rgba="0.5 0.5 0.5 1.0"/>
  </material>
  <!-- World -->
  <gazebo reference="world"/>
  <gazebo reference="link1">
    <kp>1000000.0</kp>
    <kd>100.0</kd>
    <mu1>30.0</mu1>
    <mu2>30.0</mu2>
    <maxVel>1.0</maxVel>
    <minDepth>0.001</minDepth>
    <material>Gazebo/DarkGrey</material>
  </gazebo>
  <gazebo reference="link2">
    <kp>1000000.0</kp>
    <kd>100.0</kd>
    <mu1>30.0</mu1>
    <mu2>30.0</mu2>
    <maxVel>1.0</maxVel>
    <minDepth>0.001</minDepth>
    <material>Gazebo/DarkGrey</material>
  </gazebo>
  <gazebo reference="link3">
    <kp>1000000.0</kp>
    <kd>100.0</kd>
    <mu1>30.0</mu1>
    <mu2>30.0</mu2>
    <maxVel>1.0</maxVel>
    <minDepth>0.001</minDepth>
    <material>Gazebo/DarkGrey</material>
  </gazebo>
  <gazebo reference="link4">
    <kp>1000000.0</kp>
    <kd>100.0</kd>
    <mu1>30.0</mu1>
    <mu2>30.0</mu2>
    <maxVel>1.0</maxVel>
    <minDepth>0.001</minDepth>
    <material>Gazebo/DarkGrey</material>
  </gazebo>
  <gazebo reference="link5">
    <kp>1000000.0</kp>
    <kd>100.0</kd>
    <mu1>30.0</mu1>
    <mu2>30.0</mu2>
    <maxVel>1.0</maxVel>
    <minDepth>0.001</minDepth>
    <material>Gazebo/DarkGrey</material>
  </gazebo>
  <gazebo reference="gripper_link">
    <kp>1000000.0</kp>
    <kd>100.0</kd>
    <mu1>30.0</mu1>
    <mu2>30.0</mu2>
    <maxVel>1.0</maxVel>
    <minDepth>0.001</minDepth>
    <material>Gazebo/DarkGrey</material>
  </gazebo>
  <gazebo reference="gripper_link_sub">
    <kp>1000000.0</kp>
    <kd>100.0</kd>
    <mu1>30.0</mu1>
    <mu2>30.0</mu2>
    <maxVel>1.0</maxVel>
    <minDepth>0.001</minDepth>
    <material>Gazebo/DarkGrey</material>
  </gazebo>
  <!-- end effector link -->
  <gazebo reference="end_effector_link">
    <material>Gazebo/Red</material>
  </gazebo>
  <ros2_control name="GazeboSystem" type="system">
    <hardware>
      <plugin>gazebo_ros2_control/GazeboSystem</plugin>
    </hardware>
    <joint name="joint1">
      <command_interface name="position">
        <param name="min">-2.82743338823</param>
        <param name="max">2.82743338823</param>
      </command_interface>
      <state_interface name="position"/>
      <state_interface name="velocity"/>
      <state_interface name="effort"/>
    </joint>
  </ros2_control>
  <ros2_control name="GazeboSystem" type="system">
    <hardware>
      <plugin>gazebo_ros2_control/GazeboSystem</plugin>
    </hardware>
    <joint name="joint2">
      <command_interface name="position">
        <param name="min">-1.79070781255</param>
        <param name="max">1.57079632679</param>
      </command_interface>
      <state_interface name="position"/>
      <state_interface name="velocity"/>
      <state_interface name="effort"/>
    </joint>
  </ros2_control>
  <ros2_control name="GazeboSystem" type="system">
    <hardware>
      <plugin>gazebo_ros2_control/GazeboSystem</plugin>
    </hardware>
    <joint name="joint3">
      <command_interface name="position">
        <param name="min">-0.94247779607</param>
        <param name="max">1.38230076758</param>
      </command_interface>
      <state_interface name="position"/>
      <state_interface name="velocity"/>
      <state_interface name="effort"/>
    </joint>
  </ros2_control>
  <ros2_control name="GazeboSystem" type="system">
    <hardware>
      <plugin>gazebo_ros2_control/GazeboSystem</plugin>
    </hardware>
    <joint name="joint4">
      <command_interface name="position">
        <param name="min">-1.79070781255</param>
        <param name="max">2.04203522483</param>
      </command_interface>
      <state_interface name="position"/>
      <state_interface name="velocity"/>
      <state_interface name="effort"/>
    </joint>
  </ros2_control>
  <ros2_control name="GazeboSystem" type="system">
    <hardware>
      <plugin>gazebo_ros2_control/GazeboSystem</plugin>
    </hardware>
    <joint name="gripper">
      <command_interface name="effort">
        <param name="min">-1</param>
        <param name="max">1</param>
      </command_interface>
      <state_interface name="position"/>
      <state_interface name="velocity"/>
      <state_interface name="effort"/>
    </joint>
  </ros2_control>
  <ros2_control name="GazeboSystem" type="system">
    <hardware>
      <plugin>gazebo_ros2_control/GazeboSystem</plugin>
    </hardware>
    <joint name="gripper_sub">
      <command_interface name="effort">
        <param name="min">-1</param>
        <param name="max">1</param>
      </command_interface>
      <state_interface name="position"/>
      <state_interface name="velocity"/>
      <state_interface name="effort"/>
    </joint>
  </ros2_control>
  <gazebo>
    <plugin filename="libgazebo2_ros_control.so" name="gazebo_ros2_control">
      <robot_param>robot_description</robot_param>
      <robot_param_node>robot_state_publisher</robot_param_node>
      <parameters>/home/robo/dev_ws/install/turtlebot3_manipulation_gazebo/share/turtlebot3_manipulation_gazebo/config/gz_controller.yaml</parameters>
      <!--      <controlPeriod>0.001</controlPeriod>-->
      <!--      <robotSimType>gazebo_ros_control/DefaultRobotHWSim</robotSimType>-->
    </plugin>
  </gazebo>
  <!-- loading plugin - mimic joints works in gazebo now - HASN'T BEEN PORTED TO ROS2 YET -->
  <!--  <gazebo>-->
  <!--    <plugin name="gazebo_gripper_ros_control" filename="libroboticsgroup_gazebo_mimic_joint_plugin.so">-->
  <!--      <joint>gripper</joint>-->
  <!--      <mimicJoint>gripper_sub</mimicJoint>-->
  <!--      <multiplier>1.0</multiplier>-->
  <!--      <offset>0.0</offset>-->
  <!--    </plugin>-->
  <!--  </gazebo> -->
  <!-- camera -->
  <!-- Noise is sampled independently per pixel on each frame.
        That pixel's noise value is added to each of its color
        channels, which at that point lie in the range [0,1]. -->
  <!-- <gazebo reference="camera_link">
    <sensor type="camera" name="intel_realsense_r200">
      <update_rate>30.0</update_rate>
      <camera name="head">
        <horizontal_fov>1.02974</horizontal_fov>
        <image>
          <width>1920</width>
          <height>1080</height>
          <format>R8G8B8</format>
        </image>
        <clip>
          <near>0.02</near>
          <far>300</far>
        </clip>
        <noise>
          <type>gaussian</type>
          <mean>0.0</mean>
          <stddev>0.007</stddev>
        </noise>
      </camera>
      <plugin name="camera_controller" filename="libgazebo_ros_camera.so">
        <alwaysOn>true</alwaysOn>
        <updateRate>0.0</updateRate>
        <cameraName>camera/color</cameraName>
        <imageTopicName>image_raw</imageTopicName>
        <cameraInfoTopicName>camera_info</cameraInfoTopicName>
        <frameName>camera_link</frameName>
        <hackBaseline>0.07</hackBaseline>
        <distortionK1>0.0</distortionK1>
        <distortionK2>0.0</distortionK2>
        <distortionK3>0.0</distortionK3>
        <distortionT1>0.0</distortionT1>
        <distortionT2>0.0</distortionT2>
      </plugin>
    </sensor>
  </gazebo> -->
  <transmission name="tran1">
    <type>transmission_interface/SimpleTransmission</type>
    <joint name="joint1">
      <hardwareInterface>hardware_interface/PositionJointInterface</hardwareInterface>
    </joint>
    <actuator name="motor1">
      <mechanicalReduction>1</mechanicalReduction>
    </actuator>
  </transmission>
  <transmission name="tran2">
    <type>transmission_interface/SimpleTransmission</type>
    <joint name="joint2">
      <hardwareInterface>hardware_interface/PositionJointInterface</hardwareInterface>
    </joint>
    <actuator name="motor2">
      <mechanicalReduction>1</mechanicalReduction>
    </actuator>
  </transmission>
  <transmission name="tran3">
    <type>transmission_interface/SimpleTransmission</type>
    <joint name="joint3">
      <hardwareInterface>hardware_interface/PositionJointInterface</hardwareInterface>
    </joint>
    <actuator name="motor3">
      <mechanicalReduction>1</mechanicalReduction>
    </actuator>
  </transmission>
  <transmission name="tran4">
    <type>transmission_interface/SimpleTransmission</type>
    <joint name="joint4">
      <hardwareInterface>hardware_interface/PositionJointInterface</hardwareInterface>
    </joint>
    <actuator name="motor4">
      <mechanicalReduction>1</mechanicalReduction>
    </actuator>
  </transmission>
  <transmission name="tran5">
    <type>transmission_interface/SimpleTransmission</type>
    <joint name="gripper">
      <hardwareInterface>hardware_interface/EffortJointInterface</hardwareInterface>
    </joint>
    <actuator name="motor5">
      <mechanicalReduction>1</mechanicalReduction>
    </actuator>
  </transmission>
  <transmission name="tran6">
    <type>transmission_interface/SimpleTransmission</type>
    <joint name="gripper_sub">
      <hardwareInterface>hardware_interface/EffortJointInterface</hardwareInterface>
    </joint>
    <actuator name="motor6">
      <mechanicalReduction>1</mechanicalReduction>
    </actuator>
  </transmission>
  <!-- Link 1 -->
  <link name="link1">
    <visual>
      <origin rpy="0 0 0" xyz="0 0 0"/>
      <geometry>
        <mesh filename="package://open_manipulator_x_description/meshes/chain_link1.stl" scale="0.001 0.001 0.001"/>
      </geometry>
      <material name="grey"/>
    </visual>
    <collision>
      <origin rpy="0 0 0" xyz="0 0 0"/>
      <geometry>
        <mesh filename="package://open_manipulator_x_description/meshes/chain_link1.stl" scale="0.001 0.001 0.001"/>
      </geometry>
    </collision>
    <inertial>
      <origin xyz="3.0876154e-04 0.0000000e+00 -1.2176461e-04"/>
      <mass value="7.9119962e-02"/>
      <inertia ixx="1.2505234e-05" ixy="0.0" ixz="-1.7855208e-07" iyy="2.1898364e-05" iyz="0.0" izz="1.9267361e-05"/>
    </inertial>
  </link>
  <!-- Joint 1 -->
  <joint name="joint1" type="revolute">
    <parent link="link1"/>
    <child link="link2"/>
    <origin rpy="0 0 0" xyz="0.012 0.0 0.017"/>
    <axis xyz="0 0 1"/>
    <limit effort="1" lower="-2.82743338823" upper="2.82743338823" velocity="4.8"/>
  </joint>
  <!--  Link 2 -->
  <link name="link2">
    <visual>
      <origin rpy="0 0 0" xyz="0 0 0.019"/>
      <geometry>
        <mesh filename="package://open_manipulator_x_description/meshes/chain_link2.stl" scale="0.001 0.001 0.001"/>
      </geometry>
      <material name="grey"/>
    </visual>
    <collision>
      <origin rpy="0 0 0" xyz="0 0 0.019"/>
      <geometry>
        <mesh filename="package://open_manipulator_x_description/meshes/chain_link2.stl" scale="0.001 0.001 0.001"/>
      </geometry>
    </collision>
    <inertial>
      <origin xyz="-3.0184870e-04 5.4043684e-04 0.047433464e-02"/>
      <mass value="9.8406837e-02"/>
      <inertia ixx="3.4543422e-05" ixy="-1.6031095e-08" ixz="-3.8375155e-07" iyy="3.2689329e-05" iyz="2.8511935e-08" izz="1.8850320e-05"/>
    </inertial>
  </link>
  <!--  Joint 2 -->
  <joint name="joint2" type="revolute">
    <parent link="link2"/>
    <child link="link3"/>
    <origin rpy="0 0 0" xyz="0.0 0.0 0.0595"/>
    <axis xyz="0 1 0"/>
    <limit effort="1" lower="-1.79070781255" upper="1.57079632679" velocity="4.8"/>
  </joint>
  <!--  Link 3 -->
  <link name="link3">
    <visual>
      <origin rpy="0 0 0" xyz="0 0 0"/>
      <geometry>
        <mesh filename="package://open_manipulator_x_description/meshes/chain_link3.stl" scale="0.001 0.001 0.001"/>
      </geometry>
      <material name="grey"/>
    </visual>
    <collision>
      <origin rpy="0 0 0" xyz="0 0 0"/>
      <geometry>
        <mesh filename="package://open_manipulator_x_description/meshes/chain_link3.stl" scale="0.001 0.001 0.001"/>
      </geometry>
    </collision>
    <inertial>
      <origin xyz="1.0308393e-02 3.7743363e-04 1.0170197e-01"/>
      <mass value="1.3850917e-01"/>
      <inertia ixx="3.3055381e-04" ixy="-9.7940978e-08" ixz="-3.8505711e-05" iyy="3.4290447e-04" iyz="-1.5717516e-06" izz="6.0346498e-05"/>
    </inertial>
  </link>
  <!--  Joint 3 -->
  <joint name="joint3" type="revolute">
    <parent link="link3"/>
    <child link="link4"/>
    <origin rpy="0 0 0" xyz="0.024 0 0.128"/>
    <axis xyz="0 1 0"/>
    <limit effort="1" lower="-0.94247779607" upper="1.38230076758" velocity="4.8"/>
  </joint>
  <!--  Link 4 -->
  <link name="link4">
    <visual>
      <origin rpy="0 0 0" xyz="0 0 0"/>
      <geometry>
        <mesh filename="package://open_manipulator_x_description/meshes/chain_link4.stl" scale="0.001 0.001 0.001"/>
      </geometry>
      <material name="grey"/>
    </visual>
    <collision>
      <origin rpy="0 0 0" xyz="0 0 0"/>
      <geometry>
        <mesh filename="package://open_manipulator_x_description/meshes/chain_link4.stl" scale="0.001 0.001 0.001"/>
      </geometry>
    </collision>
    <inertial>
      <origin xyz="9.0909590e-02 3.8929816e-04 2.2413279e-04"/>
      <mass value="1.3274562e-01"/>
      <inertia ixx="3.0654178e-05" ixy="-1.2764155e-06" ixz="-2.6874417e-07" iyy="2.4230292e-04" iyz="1.1559550e-08" izz="2.5155057e-04"/>
    </inertial>
  </link>
  <!--  Joint 4 -->
  <joint name="joint4" type="revolute">
    <parent link="link4"/>
    <child link="link5"/>
    <origin rpy="0 0 0" xyz="0.124 0.0 0.0"/>
    <axis xyz="0 1 0"/>
    <limit effort="1" lower="-1.79070781255" upper="2.04203522483" velocity="4.8"/>
  </joint>
  <!--  Link 5 -->
  <link name="link5">
    <visual>
      <origin rpy="0 0 0" xyz="0 0 0"/>
      <geometry>
        <mesh filename="package://open_manipulator_x_description/meshes/chain_link5.stl" scale="0.001 0.001 0.001"/>
      </geometry>
      <material name="grey"/>
    </visual>
    <collision>
      <origin rpy="0 0 0" xyz="0 0 0"/>
      <geometry>
        <mesh filename="package://open_manipulator_x_description/meshes/chain_link5.stl" scale="0.001 0.001 0.001"/>
      </geometry>
    </collision>
    <inertial>
      <origin xyz="4.4206755e-02 3.6839985e-07 8.9142216e-03"/>
      <mass value="1.4327573e-01"/>
      <inertia ixx="8.0870749e-05" ixy="0.0" ixz="-1.0157896e-06" iyy="7.5980465e-05" iyz="0.0" izz="9.3127351e-05"/>
    </inertial>
  </link>
  <!--  Gripper joint -->
  <joint name="gripper" type="prismatic">
    <parent link="link5"/>
    <child link="gripper_link"/>
    <origin rpy="0 0 0" xyz="0.0817 0.021 0.0"/>
    <axis xyz="0 1 0"/>
    <limit effort="1" lower="-0.010" upper="0.019" velocity="4.8"/>
  </joint>
  <!--  Gripper link -->
  <link name="gripper_link">
    <visual>
      <origin rpy="0 0 0" xyz="0.0 0.0 0"/>
      <geometry>
        <mesh filename="package://open_manipulator_x_description/meshes/chain_link_grip_l.stl" scale="0.001 0.001 0.001"/>
      </geometry>
      <material name="grey"/>
    </visual>
    <collision>
      <origin rpy="0 0 0" xyz="0.0 0.0 0"/>
      <geometry>
        <mesh filename="package://open_manipulator_x_description/meshes/chain_link_grip_l.stl" scale="0.001 0.001 0.001"/>
      </geometry>
    </collision>
    <inertial>
      <origin xyz="0 0 0"/>
      <mass value="1.0e-03"/>
      <inertia ixx="1.0e-03" ixy="0.0" ixz="0.0" iyy="1.0e-03" iyz="0.0" izz="1.0e-03"/>
    </inertial>
  </link>
  <!--  Gripper joint sub -->
  <joint name="gripper_sub" type="prismatic">
    <parent link="link5"/>
    <child link="gripper_link_sub"/>
    <origin rpy="0 0 0" xyz="0.0817 -0.021 0.0"/>
    <axis xyz="0 -1 0"/>
    <limit effort="1" lower="-0.010" upper="0.019" velocity="4.8"/>
    <mimic joint="gripper" multiplier="1"/>
    <!-- this might cause issues... -->
  </joint>
  <!--  Gripper link sub -->
  <link name="gripper_link_sub">
    <visual>
      <origin rpy="0 0 0" xyz="0.0 -0.0 0"/>
      <geometry>
        <mesh filename="package://open_manipulator_x_description/meshes/chain_link_grip_r.stl" scale="0.001 0.001 0.001"/>
      </geometry>
      <material name="grey"/>
    </visual>
    <collision>
      <origin rpy="0 0 0" xyz="0.0 -0.0 0"/>
      <geometry>
        <mesh filename="package://open_manipulator_x_description/meshes/chain_link_grip_r.stl" scale="0.001 0.001 0.001"/>
      </geometry>
    </collision>
    <inertial>
      <origin xyz="0 0 0"/>
      <mass value="1.0e-03"/>
      <inertia ixx="1.0e-03" ixy="0.0" ixz="0.0" iyy="1.0e-03" iyz="0.0" izz="1.0e-03"/>
    </inertial>
  </link>
  <!-- end effector joint -->
  <joint name="end_effector_joint" type="fixed">
    <origin rpy="0 0 0" xyz="0.126 0.0 0.0"/>
    <parent link="link5"/>
    <child link="end_effector_link"/>
  </joint>
  <!-- end effector link -->
  <link name="end_effector_link">
    <visual>
      <origin rpy="0 0 0" xyz="0 0 0"/>
      <geometry>
        <box size="0.01 0.01 0.01"/>
      </geometry>
      <material name="red"/>
    </visual>
    <inertial>
      <origin xyz="0 0 0"/>
      <mass value="1.0e-03"/>
      <inertia ixx="1.0e-03" ixy="0.0" ixz="0.0" iyy="1.0e-03" iyz="0.0" izz="1.0e-03"/>
    </inertial>
  </link>
  <!-- removing camera joint for now to prevent conflict with turtlebot camera joint -->
  <!-- Realsense Camera Joint Position 
  <joint name="camera_joint" type="fixed">
    <axis xyz="0 1 0" />
    <origin xyz="0.070 0.032 0.052" rpy="0 0 0"/> 
    <parent link="link5"/>
    <child link="camera_link"/>
  </joint>

  <link name="camera_link"/>
-->
  <!--  &lt;!&ndash; World &ndash;&gt;-->
  <!--  <link name="world"/>-->
  <!--  &lt;!&ndash; World fixed joint&ndash;&gt;-->
  <!--  <joint name="world_fixed" type="fixed">-->
  <!--    <origin xyz="0 0 0" rpy="0 0 0"/>-->
  <!--    <parent link="world"/>-->
  <!--    <child link="link1"/>-->
  <!--  </joint>-->
  <!-- !!!!!!!!!!!!!!!!!!!!!!!!!!!!!!!! -->
  <!-- TODO:Xacro files do not work yet -->
  <!-- !!!!!!!!!!!!!!!!!!!!!!!!!!!!!!!! -->
  <!--  <material name="black">-->
  <!--    <color rgba="0.0 0.0 0.0 1.0"/>-->
  <!--  </material>-->
  <!--  <material name="white">-->
  <!--    <color rgba="1.0 1.0 1.0 1.0"/>-->
  <!--  </material>-->
  <!--  <material name="red">-->
  <!--    <color rgba="0.8 0.0 0.0 1.0"/>-->
  <!--  </material>-->
  <!--  <material name="blue">-->
  <!--    <color rgba="0.0 0.0 0.8 1.0"/>-->
  <!--  </material>-->
  <!--  <material name="green">-->
  <!--    <color rgba="0.0 0.8 0.0 1.0"/>-->
  <!--  </material>-->
  <!--  <material name="grey">-->
  <!--    <color rgba="0.5 0.5 0.5 1.0"/>-->
  <!--  </material>-->
  <!-- Link 1 -->
  <!--  <link name="link1">-->
  <!--    <visual>-->
  <!--      <origin xyz="0 0 0" rpy="0 0 0"/>-->
  <!--      <geometry>-->
  <!--        <mesh filename="package://open_manipulator_x_description/meshes/chain_link1.stl" scale="0.001 0.001 0.001"/>-->
  <!--      </geometry>-->
  <!--      <material name="grey"/>-->
  <!--    </visual>-->
  <!--    <collision>-->
  <!--      <origin xyz="0 0 0" rpy="0 0 0"/>-->
  <!--      <geometry>-->
  <!--        <mesh filename="package://open_manipulator_x_description/meshes/chain_link1.stl" scale="0.001 0.001 0.001"/>-->
  <!--      </geometry>-->
  <!--    </collision>-->
  <!--    <inertial>-->
  <!--      <origin xyz="3.0876154e-04 0.0000000e+00 -1.2176461e-04" />-->
  <!--      <mass value="7.9119962e-02" />-->
  <!--      <inertia ixx="1.2505234e-05" ixy="0.0" ixz="-1.7855208e-07"-->
  <!--               iyy="2.1898364e-05" iyz="0.0"-->
  <!--               izz="1.9267361e-05" />-->
  <!--    </inertial>-->
  <!--  </link>-->
  <!--  &lt;!&ndash; Joint 1 &ndash;&gt;-->
  <!--  <joint name="joint1" type="revolute">-->
  <!--    <parent link="link1"/>-->
  <!--    <child link="link2"/>-->
  <!--    <origin xyz="0.012 0.0 0.017" rpy="0 0 0"/>-->
  <!--    <axis xyz="0 0 1"/>-->
  <!--    <limit velocity="4.8" effort="1" lower="-2.82743338823" upper="2.82743338823" />-->
  <!--  </joint>-->
  <!--  &lt;!&ndash;  Link 2 &ndash;&gt;-->
  <!--  <link name="link2">-->
  <!--    <visual>-->
  <!--      <origin xyz="0 0 0.019" rpy="0 0 0"/>-->
  <!--      <geometry>-->
  <!--        <mesh filename="package://open_manipulator_x_description/meshes/chain_link2.stl" scale="0.001 0.001 0.001"/>-->
  <!--      </geometry>-->
  <!--      <material name="grey"/>-->
  <!--    </visual>-->
  <!--    <collision>-->
  <!--      <origin xyz="0 0 0.019" rpy="0 0 0"/>-->
  <!--      <geometry>-->
  <!--        <mesh filename="package://open_manipulator_x_description/meshes/chain_link2.stl" scale="0.001 0.001 0.001"/>-->
  <!--      </geometry>-->
  <!--    </collision>-->
  <!--     <inertial>-->
  <!--      <origin xyz="-3.0184870e-04 5.4043684e-04 0.047433464e-02" />-->
  <!--      <mass value="9.8406837e-02" />-->
  <!--      <inertia ixx="3.4543422e-05" ixy="-1.6031095e-08" ixz="-3.8375155e-07"-->
  <!--               iyy="3.2689329e-05" iyz="2.8511935e-08"-->
  <!--               izz="1.8850320e-05" />-->
  <!--    </inertial>-->
  <!--  </link>-->
  <!--  &lt;!&ndash;  Joint 2 &ndash;&gt;-->
  <!--  <joint name="joint2" type="revolute">-->
  <!--    <parent link="link2"/>-->
  <!--    <child link="link3"/>-->
  <!--    <origin xyz="0.0 0.0 0.0595" rpy="0 0 0"/>-->
  <!--    <axis xyz="0 1 0"/>-->
  <!--    <limit velocity="4.8" effort="1" lower="-1.79070781255" upper="1.57079632679" />-->
  <!--  </joint>-->
  <!--  &lt;!&ndash;  Link 3 &ndash;&gt;-->
  <!--  <link name="link3">-->
  <!--    <visual>-->
  <!--      <origin xyz="0 0 0" rpy="0 0 0"/>-->
  <!--      <geometry>-->
  <!--        <mesh filename="package://open_manipulator_x_description/meshes/chain_link3.stl" scale="0.001 0.001 0.001"/>-->
  <!--      </geometry>-->
  <!--      <material name="grey"/>-->
  <!--    </visual>-->
  <!--    <collision>-->
  <!--      <origin xyz="0 0 0" rpy="0 0 0"/>-->
  <!--      <geometry>-->
  <!--        <mesh filename="package://open_manipulator_x_description/meshes/chain_link3.stl" scale="0.001 0.001 0.001"/>-->
  <!--      </geometry>-->
  <!--    </collision>-->
  <!--    <inertial>-->
  <!--      <origin xyz="1.0308393e-02 3.7743363e-04 1.0170197e-01" />-->
  <!--      <mass value="1.3850917e-01" />-->
  <!--      <inertia ixx="3.3055381e-04" ixy="-9.7940978e-08" ixz="-3.8505711e-05"-->
  <!--               iyy="3.4290447e-04" iyz="-1.5717516e-06"-->
  <!--               izz="6.0346498e-05" />-->
  <!--    </inertial>-->
  <!--  </link>-->
  <!--  &lt;!&ndash;  Joint 3 &ndash;&gt;-->
  <!--  <joint name="joint3" type="revolute">-->
  <!--    <parent link="link3"/>-->
  <!--    <child link="link4"/>-->
  <!--    <origin xyz="0.024 0 0.128" rpy="0 0 0"/>-->
  <!--    <axis xyz="0 1 0"/>-->
  <!--    <limit velocity="4.8" effort="1" lower="-0.94247779607" upper="1.38230076758" />-->
  <!--  </joint>-->
  <!--  &lt;!&ndash;  Link 4 &ndash;&gt;-->
  <!--  <link name="link4">-->
  <!--    <visual>-->
  <!--      <origin xyz="0 0 0" rpy="0 0 0"/>-->
  <!--      <geometry>-->
  <!--        <mesh filename="package://open_manipulator_x_description/meshes/chain_link4.stl" scale="0.001 0.001 0.001"/>-->
  <!--      </geometry>-->
  <!--      <material name="grey"/>-->
  <!--    </visual>-->
  <!--    <collision>-->
  <!--      <origin xyz="0 0 0" rpy="0 0 0"/>-->
  <!--      <geometry>-->
  <!--        <mesh filename="package://open_manipulator_x_description/meshes/chain_link4.stl" scale="0.001 0.001 0.001"/>-->
  <!--      </geometry>-->
  <!--    </collision>-->
  <!--     <inertial>-->
  <!--      <origin xyz="9.0909590e-02 3.8929816e-04 2.2413279e-04" />-->
  <!--      <mass value="1.3274562e-01" />-->
  <!--      <inertia ixx="3.0654178e-05" ixy="-1.2764155e-06" ixz="-2.6874417e-07"-->
  <!--               iyy="2.4230292e-04" iyz="1.1559550e-08"-->
  <!--               izz="2.5155057e-04" />-->
  <!--    </inertial>-->
  <!--  </link>-->
  <!--  &lt;!&ndash;  Joint 4 &ndash;&gt;-->
  <!--  <joint name="joint4" type="revolute">-->
  <!--    <parent link="link4"/>-->
  <!--    <child link="link5"/>-->
  <!--    <origin xyz="0.124 0.0 0.0" rpy="0 0 0"/>-->
  <!--    <axis xyz="0 1 0"/>-->
  <!--    <limit velocity="4.8" effort="1" lower="-1.79070781255" upper="2.04203522483" />-->
  <!--  </joint>-->
  <!--  &lt;!&ndash;  Link 5 &ndash;&gt;-->
  <!--  <link name="link5">-->
  <!--    <visual>-->
  <!--      <origin xyz="0 0 0" rpy="0 0 0"/>-->
  <!--      <geometry>-->
  <!--        <mesh filename="package://open_manipulator_x_description/meshes/chain_link5.stl" scale="0.001 0.001 0.001"/>-->
  <!--      </geometry>-->
  <!--      <material name="grey"/>-->
  <!--    </visual>-->
  <!--    <collision>-->
  <!--      <origin xyz="0 0 0" rpy="0 0 0"/>-->
  <!--      <geometry>-->
  <!--        <mesh filename="package://open_manipulator_x_description/meshes/chain_link5.stl" scale="0.001 0.001 0.001"/>-->
  <!--      </geometry>-->
  <!--    </collision>-->
  <!--     <inertial>-->
  <!--      <origin xyz="4.4206755e-02 3.6839985e-07 8.9142216e-03" />-->
  <!--      <mass value="1.4327573e-01" />-->
  <!--      <inertia ixx="8.0870749e-05" ixy="0.0" ixz="-1.0157896e-06"-->
  <!--               iyy="7.5980465e-05" iyz="0.0"-->
  <!--               izz="9.3127351e-05" />-->
  <!--    </inertial>-->
  <!--  </link>-->
  <!--  &lt;!&ndash;  Gripper joint &ndash;&gt;-->
  <!--  <joint name="gripper" type="prismatic">-->
  <!--    <parent link="link5"/>-->
  <!--    <child link="gripper_link"/>-->
  <!--    <origin xyz="0.0817 0.021 0.0" rpy="0 0 0"/>-->
  <!--    <axis xyz="0 1 0"/>-->
  <!--    <limit velocity="4.8" effort="1" lower="-0.010" upper="0.019" />-->
  <!--  </joint>-->
  <!--  &lt;!&ndash;  Gripper link &ndash;&gt;-->
  <!--  <link name="gripper_link">-->
  <!--    <visual>-->
  <!--      <origin xyz="0.0 0.0 0" rpy="0 0 0"/>-->
  <!--      <geometry>-->
  <!--        <mesh filename="package://open_manipulator_x_description/meshes/chain_link_grip_l.stl" scale="0.001 0.001 0.001"/>-->
  <!--      </geometry>-->
  <!--      <material name="grey"/>-->
  <!--    </visual>-->
  <!--    <collision>-->
  <!--      <origin xyz="0.0 0.0 0" rpy="0 0 0"/>-->
  <!--      <geometry>-->
  <!--        <mesh filename="package://open_manipulator_x_description/meshes/chain_link_grip_l.stl" scale="0.001 0.001 0.001"/>-->
  <!--      </geometry>-->
  <!--    </collision>-->
  <!--    <inertial>-->
  <!--      <origin xyz="0 0 0" />-->
  <!--      <mass value="1.0e-03" />-->
  <!--      <inertia ixx="1.0e-03" ixy="0.0" ixz="0.0"-->
  <!--               iyy="1.0e-03" iyz="0.0"-->
  <!--               izz="1.0e-03" />-->
  <!--    </inertial>-->
  <!--  </link>-->
  <!--  &lt;!&ndash;  Gripper joint sub &ndash;&gt;-->
  <!--  <joint name="gripper_sub" type="prismatic">-->
  <!--    <parent link="link5"/>-->
  <!--    <child link="gripper_link_sub"/>-->
  <!--    <origin xyz="0.0817 -0.021 0.0" rpy="0 0 0"/>-->
  <!--    <axis xyz="0 -1 0"/>-->
  <!--    <limit velocity="4.8" effort="1" lower="-0.010" upper="0.019" />-->
  <!--    <mimic joint="gripper" multiplier="1"/>-->
  <!--  </joint>-->
  <!--  &lt;!&ndash;  Gripper link sub &ndash;&gt;-->
  <!--  <link name="gripper_link_sub">-->
  <!--    <visual>-->
  <!--      <origin xyz="0.0 -0.0 0" rpy="0 0 0"/>-->
  <!--      <geometry>-->
  <!--        <mesh filename="package://open_manipulator_x_description/meshes/chain_link_grip_r.stl" scale="0.001 0.001 0.001"/>-->
  <!--      </geometry>-->
  <!--      <material name="grey"/>-->
  <!--    </visual>-->
  <!--    <collision>-->
  <!--      <origin xyz="0.0 -0.0 0" rpy="0 0 0"/>-->
  <!--      <geometry>-->
  <!--        <mesh filename="package://open_manipulator_x_description/meshes/chain_link_grip_r.stl" scale="0.001 0.001 0.001"/>-->
  <!--      </geometry>-->
  <!--    </collision>-->
  <!--    <inertial>-->
  <!--      <origin xyz="0 0 0" />-->
  <!--      <mass value="1.0e-03" />-->
  <!--      <inertia ixx="1.0e-03" ixy="0.0" ixz="0.0"-->
  <!--               iyy="1.0e-03" iyz="0.0"-->
  <!--               izz="1.0e-03" />-->
  <!--    </inertial>-->
  <!--  </link>-->
  <!--  &lt;!&ndash; end effector joint &ndash;&gt;-->
  <!--  <joint name="end_effector_joint" type="fixed">-->
  <!--    <origin xyz="0.126 0.0 0.0" rpy="0 0 0"/>-->
  <!--    <parent link="link5"/>-->
  <!--    <child link="end_effector_link"/>-->
  <!--  </joint>-->
  <!--  &lt;!&ndash; end effector link &ndash;&gt;-->
  <!--  <link name="end_effector_link">-->
  <!--    <visual>-->
  <!--      <origin xyz="0 0 0" rpy="0 0 0"/>-->
  <!--      <geometry>-->
  <!--        <box size="0.01 0.01 0.01" />-->
  <!--      </geometry>-->
  <!--      <material name="red"/>-->
  <!--     </visual>-->
  <!--    <inertial>-->
  <!--      <origin xyz="0 0 0" />-->
  <!--      <mass value="1.0e-03" />-->
  <!--      <inertia ixx="1.0e-03" ixy="0.0" ixz="0.0"-->
  <!--               iyy="1.0e-03" iyz="0.0"-->
  <!--               izz="1.0e-03" />-->
  <!--    </inertial>-->
  <!--  </link>-->
  <!--  &lt;!&ndash; Realsense Camera Joint Position &ndash;&gt;-->
  <!--  <joint name="camera_joint" type="fixed">-->
  <!--    <axis xyz="0 1 0" />-->
  <!--    <origin xyz="0.070 0.032 0.052" rpy="0 0 0"/> -->
  <!--    <parent link="link5"/>-->
  <!--    <child link="camera_link"/>-->
  <!--  </joint>-->
  <!--  <link name="camera_link"/>-->
</robot>
