<?xml version="1.0"?>
<!-- TurtleBot3 Manipulation -->
<robot name="turtlebot3_pi" xmlns:xacro="http://ros.org/wiki/xacro">

  <!--  if gazebo=True, enable SDF specific tags  -->
  <xacro:arg name="gazebo" default="True"/>
  <xacro:arg name="offroad_turtlebot" default="False"/>
  <xacro:arg name="scale_factor" default="1.0"/>
  <xacro:property name="sf" value="$(arg scale_factor)"/>

  <!--  Begin Model Description  -->
  <link name="base_footprint"/>
  <link name="base_link">
    <visual>
      <origin xyz="-0.064 0 0.0" rpy="0 0 0"/>
      <geometry>
        <mesh filename="file://$(find turtlebot3_description)/meshes/bases/waffle_pi_base.stl" scale="0.001 0.001 0.001"/>
      </geometry>
      <material name="light_black"/>
    </visual>

    <collision>
      <origin xyz="-0.064 0 0.047" rpy="0 0 0"/>
      <geometry>
        <box size="0.266 0.266 0.094"/>
      </geometry>
    </collision>

    <inertial>
      <origin xyz="0 0 0" rpy="0 0 0"/>
      <mass value="1.3729096e+00"/>
      <inertia ixx="8.7002718e-03" ixy="-4.7576583e-05" ixz="1.1160499e-04"
               iyy="8.6195418e-03" iyz="-3.5422299e-06"
               izz="1.4612727e-02" />
    </inertial>
  </link>
  <joint name="base_joint" type="fixed">
    <parent link="base_footprint"/>
    <child link="base_link" />
    <origin xyz="0 0 0.010" rpy="0 0 0"/>
  </joint>


  <xacro:if value="$(arg offroad_turtlebot)">
    <link name="wheel_left_link">
      <visual>
        <origin xyz="0 0 0" rpy="1.57 0 0"/>
        <geometry>
          <mesh filename="file://$(find turtlebot3_description)/meshes/wheels/left_tire.stl" scale="${0.001 * sf} ${0.001 * sf} ${0.001 * sf}"/>
        </geometry>
        <material name="dark"/>
      </visual>

      <collision>
        <origin xyz="0 0 0" rpy="0 0 0"/>
        <geometry>
          <cylinder length="${0.018 * sf}" radius="${sf * 0.033}"/>
        </geometry>
      </collision>

      <inertial>
        <origin xyz="0 0 0" />
        <mass value="${sf**3 * 2.8498940e-02}" />
        <inertia ixx="${sf**3 * 1.1175580e-05}" ixy="${sf**3 * -4.2369783e-11}" ixz="${sf**3 * -5.9381719e-09}"
                 iyy="${sf**3 * 1.1192413e-05}" iyz="${sf**3 * -1.4400107e-11}"
                 izz="${sf**3 * 2.0712558e-05}" />
        </inertial>
    </link>
    <joint name="wheel_left_joint" type="continuous">
      <parent link="base_link"/>
      <child link="wheel_left_link"/>
      <origin xyz="0.0 0.144 0.023" rpy="-1.57 0 0"/>
      <axis xyz="0 0 1"/>
      <xacro:if value="$(arg gazebo)">
        <dynamics damping="0.2" friction="0.5"/>
      </xacro:if>
    </joint>

    <link name="wheel_right_link">
      <visual>
        <origin xyz="0 0 0" rpy="1.57 0 0"/>
        <geometry>
          <mesh filename="file://$(find turtlebot3_description)/meshes/wheels/left_tire.stl" scale="${0.001 * sf} ${0.001 * sf} ${0.001 * sf}"/>
        </geometry>
        <material name="dark"/>
      </visual>

      <collision>
        <origin xyz="0 0 0" rpy="0 0 0"/>
        <geometry>
          <cylinder length="${0.018 * sf}" radius="${sf * 0.033}"/>
        </geometry>
      </collision>

      <inertial>
        <origin xyz="0 0 0" />
        <mass value="${sf**3 * 2.8498940e-02}" />
        <inertia ixx="${sf**3 * 1.1175580e-05}" ixy="${sf**3 * -4.2369783e-11}" ixz="${sf**3 * -5.9381719e-09}"
                 iyy="${sf**3 * 1.1192413e-05}" iyz="${sf**3 * -1.4400107e-11}"
                 izz="${sf**3 * 2.0712558e-05}" />
        </inertial>
    </link>
    <joint name="wheel_right_joint" type="continuous">
      <parent link="base_link"/>
      <child link="wheel_right_link"/>
      <origin xyz="0.0 -0.144 0.023" rpy="-1.57 0 0"/>
      <axis xyz="0 0 1"/>
      <xacro:if value="$(arg gazebo)">
        <dynamics damping="0.2" friction="0.5"/>
      </xacro:if>
    </joint>

    <link name="caster_back_right_link">

      <visual>
        <origin xyz="0 0 0" rpy="0 0 0"/>
        <geometry>
          <sphere radius="${0.033 * sf - 0.028}"/>
        </geometry>
      </visual>

      <collision>
        <origin xyz="0 0 0" rpy="0 0 0"/>
        <geometry>
          <sphere radius="${0.033 * sf - 0.028}"/>
        </geometry>
      </collision>

      <inertial>
        <origin xyz="0 0 0" />
        <mass value="${sf**3 * 0.005}" />
        <inertia ixx="${sf**3 * 0.001}" ixy="${sf**3 * 0.0}" ixz="${sf**3 * 0.0}"
                 iyy="${sf**3 * 0.001}" iyz="${sf**3 * 0.0}"
                 izz="${sf**3 * 0.001}" />
      </inertial>
    </link>
    <xacro:if value="$(arg gazebo)">
      <!-- Represent ball joint by 2 additional links and joints   -->
      <link name="caster_back_right_link_proxy1">
        <inertial>
          <origin xyz="0 0 0" />
          <mass value="0.005" />
          <inertia ixx="0.001" ixy="0.0" ixz="0.0"
                   iyy="0.001" iyz="0.0"
                   izz="0.001" />
        </inertial>
      </link>

      <link name="caster_back_right_link_proxy2">
        <inertial>
          <origin xyz="0 0 0" />
          <mass value="0.005" />
          <inertia ixx="0.001" ixy="0.0" ixz="0.0"
                   iyy="0.001" iyz="0.0"
                   izz="0.001" />
        </inertial>
      </link>

      <joint name="caster_back_right_joint_x" type="continuous">
        <parent link="base_link"/>
        <child link="caster_back_right_link_proxy1"/>
        <origin xyz="-0.177 -0.064 -0.005" rpy="-1.57 0 0"/>
        <axis xyz="1 0 0"/>
        <dynamics damping="0.1" friction="0.2"/>
      </joint>
      <joint name="caster_back_right_joint_y" type="continuous">
        <parent link="caster_back_right_link_proxy1"/>
        <child link="caster_back_right_link_proxy2"/>
        <origin xyz="0 0 0" rpy="0 0 0"/>
        <axis xyz="0 1 0"/>
        <dynamics damping="0.1" friction="0.2"/>
      </joint>
      <joint name="caster_back_right_joint_z" type="continuous">
        <parent link="caster_back_right_link_proxy2"/>
        <child link="caster_back_right_link"/>
        <origin xyz="0 0 0" rpy="0 0 0"/>
        <axis xyz="0 0 1"/>
       <dynamics damping="0.1" friction="0.2"/>
      </joint>
    </xacro:if>

    <xacro:if value="${not $(arg gazebo)}">
      <joint name="caster_back_right_joint" type="fixed">
        <parent link="base_link"/>
        <child link="caster_back_right_link"/>
        <origin xyz="-0.177 -0.064 -0.004" rpy="-1.57 0 0"/>
      </joint>
    </xacro:if>

    <link name="caster_back_left_link">

      <visual>
        <origin xyz="0 0 0" rpy="0 0 0"/>
        <geometry>
          <sphere radius="${0.033 * sf - 0.028}"/>
        </geometry>
      </visual>

      <collision>
        <origin xyz="0 0 0" rpy="0 0 0"/>
        <geometry>
          <sphere radius="${0.033 * sf - 0.028}"/>
        </geometry>
      </collision>

      <inertial>
        <origin xyz="0 0 0" />
        <mass value="${sf**3 * 0.005}" />
        <inertia ixx="${sf**3 * 0.001}" ixy="${sf**3 * 0.0}" ixz="${sf**3 * 0.0}"
                 iyy="${sf**3 * 0.001}" iyz="${sf**3 * 0.0}"
                 izz="${sf**3 * 0.001}" />
      </inertial>
    </link>
    <xacro:if value="$(arg gazebo)">
      <!-- Represent ball joint by 2 additional links and joints   -->
      <link name="caster_back_left_link_proxy1">
        <inertial>
          <origin xyz="0 0 0" />
          <mass value="0.005" />
          <inertia ixx="0.001" ixy="0.0" ixz="0.0"
                   iyy="0.001" iyz="0.0"
                   izz="0.001" />
        </inertial>
      </link>

      <link name="caster_back_left_link_proxy2">
        <inertial>
          <origin xyz="0 0 0" />
          <mass value="0.005" />
          <inertia ixx="0.001" ixy="0.0" ixz="0.0"
                   iyy="0.001" iyz="0.0"
                   izz="0.001" />
        </inertial>
      </link>

      <joint name="caster_back_left_joint_x" type="continuous">
        <parent link="base_link"/>
        <child link="caster_back_left_link_proxy1"/>
        <origin xyz="-0.177 0.064 -0.005" rpy="-1.57 0 0"/>
        <axis xyz="1 0 0"/>
        <dynamics damping="0.1" friction="0.2"/>
      </joint>
      <joint name="caster_back_left_joint_y" type="continuous">
        <parent link="caster_back_left_link_proxy1"/>
        <child link="caster_back_left_link_proxy2"/>
        <origin xyz="0 0 0" rpy="0 0 0"/>
        <axis xyz="0 1 0"/>
        <dynamics damping="0.1" friction="0.2"/>
      </joint>
      <joint name="caster_back_left_joint_z" type="continuous">
        <parent link="caster_back_left_link_proxy2"/>
        <child link="caster_back_left_link"/>
        <origin xyz="0 0 0" rpy="0 0 0"/>
        <axis xyz="0 0 1"/>
        <dynamics damping="0.1" friction="0.2"/>
      </joint>
    </xacro:if>

    <xacro:if value="${not $(arg gazebo)}">
      <joint name="caster_back_left_joint" type="fixed">
        <parent link="base_link"/>
        <child link="caster_back_left_link"/>
        <origin xyz="-0.177 0.064 -0.004" rpy="-1.57 0 0"/>
      </joint>
    </xacro:if>

  </xacro:if>

  <xacro:if value="${not $(arg offroad_turtlebot)}">
    <link name="wheel_left_link">
      <visual>
        <origin xyz="0 0 0" rpy="1.57 0 0"/>
        <geometry>
          <mesh filename="file://$(find turtlebot3_description)/meshes/wheels/left_tire.stl" scale="0.001 0.001 0.001"/>
        </geometry>
        <material name="dark"/>
      </visual>

      <collision>
        <origin xyz="0 0 0" rpy="0 0 0"/>
        <geometry>
          <cylinder length="0.018" radius="0.033"/>
        </geometry>
      </collision>

      <inertial>
        <origin xyz="0 0 0" />
        <mass value="2.8498940e-02" />
        <inertia ixx="1.1175580e-05" ixy="-4.2369783e-11" ixz="-5.9381719e-09"
                 iyy="1.1192413e-05" iyz="-1.4400107e-11"
                 izz="2.0712558e-05" />
        </inertial>
    </link>
    <joint name="wheel_left_joint" type="continuous">
      <parent link="base_link"/>
      <child link="wheel_left_link"/>
      <origin xyz="0.0 0.144 0.023" rpy="-1.57 0 0"/>
      <axis xyz="0 0 1"/>
      <xacro:if value="$(arg gazebo)">
        <dynamics damping="0.2" friction="0.5"/>
      </xacro:if>
    </joint>

    <link name="wheel_right_link">
      <visual>
        <origin xyz="0 0 0" rpy="1.57 0 0"/>
        <geometry>
          <mesh filename="file://$(find turtlebot3_description)/meshes/wheels/right_tire.stl" scale="0.001 0.001 0.001"/>
        </geometry>
        <material name="dark"/>
      </visual>

      <collision>
        <origin xyz="0 0 0" rpy="0 0 0"/>
        <geometry>
          <cylinder length="0.018" radius="0.033"/>
        </geometry>
      </collision>

      <inertial>
        <origin xyz="0 0 0" />
        <mass value="2.8498940e-02" />
        <inertia ixx="1.1175580e-05" ixy="-4.2369783e-11" ixz="-5.9381719e-09"
                 iyy="1.1192413e-05" iyz="-1.4400107e-11"
                 izz="2.0712558e-05" />
        </inertial>
    </link>
    <joint name="wheel_right_joint" type="continuous">
      <parent link="base_link"/>
      <child link="wheel_right_link"/>
      <origin xyz="0.0 -0.144 0.023" rpy="-1.57 0 0"/>
      <axis xyz="0 0 1"/>
      <xacro:if value="$(arg gazebo)">
        <dynamics damping="0.2" friction="0.5"/>
      </xacro:if>
    </joint>


    <link name="caster_back_right_link">

      <visual>
        <origin xyz="0 0 0" rpy="0 0 0"/>
        <geometry>
          <sphere radius="0.005"/>
        </geometry>
      </visual>

      <collision>
        <origin xyz="0 0 0" rpy="0 0 0"/>
        <geometry>
          <sphere radius="0.005"/>
        </geometry>
      </collision>

      <inertial>
        <origin xyz="0 0 0" />
        <mass value="0.005" />
        <inertia ixx="0.001" ixy="0.0" ixz="0.0"
                 iyy="0.001" iyz="0.0"
                 izz="0.001" />
      </inertial>
    </link>
    <xacro:if value="$(arg gazebo)">
      <!-- Represent ball joint by 2 additional links and joints   -->
      <link name="caster_back_right_link_proxy1">
        <inertial>
          <origin xyz="0 0 0" />
          <mass value="0.005" />
          <inertia ixx="0.001" ixy="0.0" ixz="0.0"
                   iyy="0.001" iyz="0.0"
                   izz="0.001" />
        </inertial>
      </link>

      <link name="caster_back_right_link_proxy2">
        <inertial>
          <origin xyz="0 0 0" />
          <mass value="0.005" />
          <inertia ixx="0.001" ixy="0.0" ixz="0.0"
                   iyy="0.001" iyz="0.0"
                   izz="0.001" />
        </inertial>
      </link>

      <joint name="caster_back_right_joint_x" type="continuous">
        <parent link="base_link"/>
        <child link="caster_back_right_link_proxy1"/>
        <origin xyz="-0.177 -0.064 -0.005" rpy="-1.57 0 0"/>
        <axis xyz="1 0 0"/>
        <dynamics damping="0.1" friction="0.2"/>
      </joint>
      <joint name="caster_back_right_joint_y" type="continuous">
        <parent link="caster_back_right_link_proxy1"/>
        <child link="caster_back_right_link_proxy2"/>
        <origin xyz="0 0 0" rpy="0 0 0"/>
        <axis xyz="0 1 0"/>
        <dynamics damping="0.1" friction="0.2"/>
      </joint>
      <joint name="caster_back_right_joint_z" type="continuous">
        <parent link="caster_back_right_link_proxy2"/>
        <child link="caster_back_right_link"/>
        <origin xyz="0 0 0" rpy="0 0 0"/>
        <axis xyz="0 0 1"/>
       <dynamics damping="0.1" friction="0.2"/>
      </joint>
    </xacro:if>

    <xacro:if value="${not $(arg gazebo)}">
      <joint name="caster_back_right_joint" type="fixed">
        <parent link="base_link"/>
        <child link="caster_back_right_link"/>
        <origin xyz="-0.177 -0.064 -0.004" rpy="-1.57 0 0"/>
      </joint>
    </xacro:if>

    <link name="caster_back_left_link">

      <visual>
        <origin xyz="0 0 0" rpy="0 0 0"/>
        <geometry>
          <sphere radius="0.005"/>
        </geometry>
      </visual>

      <collision>
        <origin xyz="0 0 0" rpy="0 0 0"/>
        <geometry>
          <sphere radius="0.005"/>
        </geometry>
      </collision>

      <inertial>
        <origin xyz="0 0 0" />
        <mass value="0.005" />
        <inertia ixx="0.001" ixy="0.0" ixz="0.0"
                 iyy="0.001" iyz="0.0"
                 izz="0.001" />
      </inertial>
    </link>
    <xacro:if value="$(arg gazebo)">
      <!-- Represent ball joint by 2 additional links and joints   -->
      <link name="caster_back_left_link_proxy1">
        <inertial>
          <origin xyz="0 0 0" />
          <mass value="0.005" />
          <inertia ixx="0.001" ixy="0.0" ixz="0.0"
                   iyy="0.001" iyz="0.0"
                   izz="0.001" />
        </inertial>
      </link>

      <link name="caster_back_left_link_proxy2">
        <inertial>
          <origin xyz="0 0 0" />
          <mass value="0.005" />
          <inertia ixx="0.001" ixy="0.0" ixz="0.0"
                   iyy="0.001" iyz="0.0"
                   izz="0.001" />
        </inertial>
      </link>

      <joint name="caster_back_left_joint_x" type="continuous">
        <parent link="base_link"/>
        <child link="caster_back_left_link_proxy1"/>
        <origin xyz="-0.177 0.064 -0.005" rpy="-1.57 0 0"/>
        <axis xyz="1 0 0"/>
        <dynamics damping="0.1" friction="0.2"/>
      </joint>
      <joint name="caster_back_left_joint_y" type="continuous">
        <parent link="caster_back_left_link_proxy1"/>
        <child link="caster_back_left_link_proxy2"/>
        <origin xyz="0 0 0" rpy="0 0 0"/>
        <axis xyz="0 1 0"/>
        <dynamics damping="0.1" friction="0.2"/>
      </joint>
      <joint name="caster_back_left_joint_z" type="continuous">
        <parent link="caster_back_left_link_proxy2"/>
        <child link="caster_back_left_link"/>
        <origin xyz="0 0 0" rpy="0 0 0"/>
        <axis xyz="0 0 1"/>
        <dynamics damping="0.1" friction="0.2"/>
      </joint>
    </xacro:if>

    <xacro:if value="${not $(arg gazebo)}">
      <joint name="caster_back_left_joint" type="fixed">
        <parent link="base_link"/>
        <child link="caster_back_left_link"/>
        <origin xyz="-0.177 0.064 -0.004" rpy="-1.57 0 0"/>
      </joint>
    </xacro:if>

  </xacro:if>

  <link name="imu_link"/>
  <joint name="imu_joint" type="fixed">
    <parent link="base_link"/>
    <child link="imu_link"/>
    <origin xyz="0.0 0 0.068" rpy="0 0 0"/>
  </joint>


  <link name="base_scan">
    <visual>
      <origin xyz="0 0 0" rpy="0 0 0"/>
      <geometry>
        <mesh filename="file://$(find turtlebot3_description)/meshes/sensors/lds.stl" scale="0.001 0.001 0.001"/>
      </geometry>
      <material name="dark"/>
    </visual>

    <collision>
      <origin xyz="0.015 0 -0.0065" rpy="0 0 0"/>
      <geometry>
        <cylinder length="0.0315" radius="0.055"/>
      </geometry>
    </collision>

    <inertial>
      <mass value="0.114" />
      <origin xyz="-0.052 0 0.111" />
      <inertia ixx="0.001" ixy="0.0" ixz="0.0"
               iyy="0.001" iyz="0.0"
               izz="0.001" />
    </inertial>
  </link>
  <joint name="scan_joint" type="fixed">
    <parent link="base_link"/>
    <child link="base_scan"/>
    <origin xyz="-0.025 0 0.122" rpy="0 0 0"/>
  </joint>

  <link name="camera_link">
    <inertial>
      <mass value="0.035" />
      <origin xyz="0 0 0" />
      <inertia ixx="0.001" ixy="0.0" ixz="0.0"
               iyy="0.001" iyz="0.0"
               izz="0.001" />
    </inertial>
    <collision>
      <origin xyz="0.005 0.011 0.013" rpy="0 0 0"/>
      <geometry>
        <box size="0.015 0.030 0.027"/>
      </geometry>
    </collision>
  </link>
  <link name="camera_rgb_optical_frame">
    <inertial>
      <mass value="0.035" />
      <origin xyz="0 0 0" />
      <inertia ixx="0.001" ixy="0.0" ixz="0.0"
               iyy="0.001" iyz="0.0"
               izz="0.001" />
    </inertial>
  </link>
  <joint name="camera_joint" type="fixed">
    <origin xyz="0.073 -0.011 0.084" rpy="0 0 0"/>
    <axis xyz="0 0 1"/>
    <parent link="base_link"/>
    <child link="camera_link"/>
  </joint>
<!--  <joint name="camera_rgb_joint" type="fixed">-->
<!--    <origin xyz="0.003 0.011 0.009" rpy="0 0 0"/>-->
<!--    <parent link="camera_link"/>-->
<!--    <child link="camera_rgb_frame"/>-->
<!--  </joint>-->
<!--  <link name="camera_rgb_frame"/>-->

  <joint name="camera_rgb_optical_joint" type="fixed">
    <origin xyz="0.003 0.011 0.009" rpy="0 0 0"/>
    <parent link="camera_link"/>
    <child link="camera_rgb_optical_frame"/>
  </joint>

</robot>
